Workbook

Sheet מחשבון
A1: מחשבון רווחיות — DentalCompare
A2: שנה רק את הערכים הכחולים. כל השאר מחושב אוטומטית.
A3: 📥 קלט — פרמטרים
A4: מספר מרפאות | B4: 100
A5: מחיר חודשי למרפאה | B5: 199
A6: מע"מ | B6: 0.18
A7: תקציב פרסום ממומן חודשי | B7: 2000
A8: עלות תשתית חודשית (hosting+DB+דומיין+מייל) | B8: 200
A9: PayPlus — עלות חשבוניות (עד 100 מסמכים) | B9: 30 | D9: Invoice4U כולל 100 מסמכים בבסיס — בלי תוספת
A11: 💳 הנחות ספקי סליקה
A12: Invoice4U — עמלת סליקה | B12: 0.009 | D12: מדרגות Invoice4U: עד 100=55, עד 200=67, עד 500=102
A13: PayPlus — תשלום חודשי קבוע | B13: 193.9
A14: PayPlus — דמי הקמה (חד פעמי) | B14: 250
A16: 📊 הכנסות
A17: הכנסה חודשית | B17: =B4*B5 -> 19900
A18: הכנסה שנתית | B18: =B17*12 -> 238800
A19: נפח מחויב בכרטיס (כולל מע"מ) | B19: =B4*B5*(1+B6) -> 23482
A21: 💳 השוואת עלות סליקה
A22: רכיב | B22: Invoice4U | C22: PayPlus
A23: בסיס / קבוע חודשי | B23: =IF(B4<=100,55,IF(B4<=200,67,102)) -> 55 | C23: =B13 -> 193.9
A24: עמלת סליקה | B24: =B19*B12 -> 211.338 | C24: 0
A25: סה"כ סליקה חודשי | B25: =B23+B24 -> 266.338 | C25: =C23+C24 -> 193.9
A27: 💰 רווחיות חודשית לפי ספק
B28: Invoice4U | C28: PayPlus
A29: הכנסה | B29: =B17 -> 19900 | C29: =B17 -> 19900
A30: (−) עלות סליקה | B30: =B25 -> 266.338 | C30: =C25 -> 193.9
A31: (−) תשתית | B31: =B8 -> 200 | C31: =B8 -> 200
A32: (−) חשבוניות | B32: 0 | C32: =B9 -> 30 | D32: Invoice4U: חשבוניות כלולות בבסיס
A33: (−) פרסום ממומן | B33: =B7 -> 2000 | C33: =B7 -> 2000
A34: סה"כ עלויות | B34: =SUM(B30:B33) -> 2466.338 | C34: =SUM(C30:C33) -> 2423.9
A35: רווח חודשי | B35: =B29-B34 -> 17433.662 | C35: =C29-C34 -> 17476.1
A36: רווח שנתי | B36: =B35*12 -> 209203.94 | C36: =C35*12 -> 209713.2
A37: שולי רווח | B37: =B35/B29 -> 0.87606342 | C37: =C35/C29 -> 0.87819598
A39: ✅ המלצה
A40: ספק מומלץ (הרווחי יותר) | B40: =IF(B35>=C35,"Invoice4U","PayPlus") -> PayPlus
A41: רווח חודשי מקסימלי | B41: =MAX(B35,C35) -> 17476.1
A42: רווח שנתי מקסימלי | B42: =MAX(B36,C36) -> 209713.2
A44: ⚖️ נקודת איזון (תרחיש PayPlus)
A45: הוצאות קבועות חודשיות | B45: =B13+B7+B8+B9 -> 2423.9 | D45: מעבר למספר זה — כל מרפאה היא רווח נקי
A46: מרפאות נדרשות לכיסוי ההוצאות | B46: =ROUNDUP(B45/B5,0) -> 13
...

Sheet תרחישים
A1: תרחישים לפי מספר מרפאות
A2: מבוסס על המחיר והעלויות מגיליון 'מחשבון'. משווה רווח חודשי בין הספקים.
A3: מרפאות | B3: הכנסה חודשית | C3: רווח PayPlus | D3: רווח Invoice4U | E3: ספק זול יותר | F3: רווח שנתי (מיטבי) | G3: שולי רווח
A4: 8 | B4: =A4*מחשבון!$B$5 -> 1592 | C4: =B4-מחשבון!$B$13-(מחשבון!$B$7+מחשבון!$B$8+מחשבון!$B$9) -> -831.9 | D4: =B4-(IF(A4<=100,55,IF(A4<=200,67,102))+A4*מחשבון!$B$5*(1+מחשבון!$B$6)*מחשבון!$B$12)-(מחשבון!$B$7+מחשבון!$B$8) -> -679.90704 | E4: =IF(C4>=D4,"PayPlus","Invoice4U") -> Invoice4U | F4: =MAX(C4,D4)*12 -> -8158.8845 | G4: =MAX(C4,D4)/B4 -> -0.42707729
A5: 25 | B5: =A5*מחשבון!$B$5 -> 4975 | C5: =B5-מחשבון!$B$13-(מחשבון!$B$7+מחשבון!$B$8+מחשבון!$B$9) -> 2551.1 | D5: =B5-(IF(A5<=100,55,IF(A5<=200,67,102))+A5*מחשבון!$B$5*(1+מחשבון!$B$6)*מחשבון!$B$12)-(מחשבון!$B$7+מחשבון!$B$8) -> 2667.1655 | E5: =IF(C5>=D5,"PayPlus","Invoice4U") -> Invoice4U | F5: =MAX(C5,D5)*12 -> 32005.986 | G5: =MAX(C5,D5)/B5 -> 0.53611367
A6: 50 | B6: =A6*מחשבון!$B$5 -> 9950 | C6: =B6-מחשבון!$B$13-(מחשבון!$B$7+מחשבון!$B$8+מחשבון!$B$9) -> 7526.1 | D6: =B6-(IF(A6<=100,55,IF(A6<=200,67,102))+A6*מחשבון!$B$5*(1+מחשבון!$B$6)*מחשבון!$B$12)-(מחשבון!$B$7+מחשבון!$B$8) -> 7589.331 | E6: =IF(C6>=D6,"PayPlus","Invoice4U") -> Invoice4U | F6: =MAX(C6,D6)*12 -> 91071.972 | G6: =MAX(C6,D6)/B6 -> 0.76274683
A7: 75 | B7: =A7*מחשבון!$B$5 -> 14925 | C7: =B7-מחשבון!$B$13-(מחשבון!$B$7+מחשבון!$B$8+מחשבון!$B$9) -> 12501.1 | D7: =B7-(IF(A7<=100,55,IF(A7<=200,67,102))+A7*מחשבון!$B$5*(1+מחשבון!$B$6)*מחשבון!$B$12)-(מחשבון!$B$7+מחשבון!$B$8) -> 12511.496 | E7: =IF(C7>=D7,"PayPlus","Invoice4U") -> Invoice4U | F7: =MAX(C7,D7)*12 -> 150137.96 | G7: =MAX(C7,D7)/B7 -> 0.83829122
A8: 100 | B8: =A8*מחשבון!$B$5 -> 19900 | C8: =B8-מחשבון!$B$13-(מחשבון!$B$7+מחשבון!$B$8+מחשבון!$B$9) -> 17476.1 | D8: =B8-(IF(A8<=100,55,IF(A8<=200,67,102))+A8*מחשבון!$B$5*(1+מחשבון!$B$6)*מחשבון!$B$12)-(מחשבון!$B$7+מחשבון!$B$8) -> 17433.662 | E8: =IF(C8>=D8,"PayPlus","Invoice4U") -> PayPlus | F8: =MAX(C8,D8)*12 -> 209713.2 | G8: =MAX(C8,D8)/B8 -> 0.87819598
A9: 150 | B9: =A9*מחשבון!$B$5 -> 29850 | C9: =B9-מחשבון!$B$13-(מחשבון!$B$7+מחשבון!$B$8+מחשבון!$B$9) -> 27426.1 | D9: =B9-(IF(A9<=100,55,IF(A9<=200,67,102))+A9*מחשבון!$B$5*(1+מחשבון!$B$6)*מחשבון!$B$12)-(מחשבון!$B$7+מחשבון!$B$8) -> 27265.993 | E9: =IF(C9>=D9,"PayPlus","Invoice4U") -> PayPlus | F9: =MAX(C9,D9)*12 -> 329113.2 | G9: =MAX(C9,D9)/B9 -> 0.91879732
A10: 200 | B10: =A10*מחשבון!$B$5 -> 39800 | C10: =B10-מחשבון!$B$13-(מחשבון!$B$7+מחשבון!$B$8+מחשבון!$B$9) -> 37376.1 | D10: =B10-(IF(A10<=100,55,IF(A10<=200,67,102))+A10*מחשבון!$B$5*(1+מחשבון!$B$6)*מחשבון!$B$12)-(מחשבון!$B$7+מחשבון!$B$8) -> 37110.324 | E10: =IF(C10>=D10,"PayPlus","Invoice4U") -> PayPlus | F10: =MAX(C10,D10)*12 -> 448513.2 | G10: =MAX(C10,D10)/B10 -> 0.93909799
A11: 300 | B11: =A11*מחשבון!$B$5 -> 59700 | C11: =B11-מחשבון!$B$13-(מחשבון!$B$7+מחשבון!$B$8+מחשבון!$B$9) -> 57276.1 | D11: =B11-(IF(A11<=100,55,IF(A11<=200,67,102))+A11*מחשבון!$B$5*(1+מחשבון!$B$6)*מחשבון!$B$12)-(מחשבון!$B$7+מחשבון!$B$8) -> 56763.986 | E11: =IF(C11>=D11,"PayPlus","Invoice4U") -> PayPlus | F11: =MAX(C11,D11)*12 -> 687313.2 | G11: =MAX(C11,D11)/B11 -> 0.95939866
A12: 500 | B12: =A12*מחשבון!$B$5 -> 99500 | C12: =B12-מחשבון!$B$13-(מחשבון!$B$7+מחשבון!$B$8+מחשבון!$B$9) -> 97076.1 | D12: =B12-(IF(A12<=100,55,IF(A12<=200,67,102))+A12*מחשבון!$B$5*(1+מחשבון!$B$6)*מחשבון!$B$12)-(מחשבון!$B$7+מחשבון!$B$8) -> 96141.31 | E12: =IF(C12>=D12,"PayPlus","Invoice4U") -> PayPlus | F12: =MAX(C12,D12)*12 -> 1164913.2 | G12: =MAX(C12,D12)/B12 -> 0.9756392
A14: 🔵 כחול = ערך שניתן לשנות | PayPlus מוגבל ל-1,000 עסקאות/חודש בתעריף הקבוע

Sheet שנה ראשונה
A1: שנה ראשונה — הצטרפות הדרגתית ותזרים מצטבר (PayPlus)
A2: שנה את 'מרפאות חדשות' (כחול) לפי קצב הגיוס הצפוי. הסכום בשורת הסיכום הוא סך המצטרפות בשנה.
A3: חודש | B3: מרפאות חדשות | C3: מרפאות פעילות | D3: הכנסה חודשית | E3: עלויות חודשיות | F3: רווח חודשי | G3: תזרים מצטבר
A4: 1 | B4: 4 | C4: =SUM($B$4:B4) -> 4 | D4: =C4*מחשבון!$B$5 -> 796 | E4: =מחשבון!$B$13+מחשבון!$B$9+מחשבון!$B$8+מחשבון!$B$7+מחשבון!$B$14 -> 2673.9 | F4: =D4-E4 -> -1877.9 | G4: =SUM($F$4:F4) -> -1877.9
A5: 2 | B5: 5 | C5: =SUM($B$4:B5) -> 9 | D5: =C5*מחשבון!$B$5 -> 1791 | E5: =מחשבון!$B$13+מחשבון!$B$9+מחשבון!$B$8+מחשבון!$B$7 -> 2423.9 | F5: =D5-E5 -> -632.9 | G5: =SUM($F$4:F5) -> -2510.8
A6: 3 | B6: 6 | C6: =SUM($B$4:B6) -> 15 | D6: =C6*מחשבון!$B$5 -> 2985 | E6: =מחשבון!$B$13+מחשבון!$B$9+מחשבון!$B$8+מחשבון!$B$7 -> 2423.9 | F6: =D6-E6 -> 561.1 | G6: =SUM($F$4:F6) -> -1949.7
A7: 4 | B7: 7 | C7: =SUM($B$4:B7) -> 22 | D7: =C7*מחשבון!$B$5 -> 4378 | E7: =מחשבון!$B$13+מחשבון!$B$9+מחשבון!$B$8+מחשבון!$B$7 -> 2423.9 | F7: =D7-E7 -> 1954.1 | G7: =SUM($F$4:F7) -> 4.4
A8: 5 | B8: 8 | C8: =SUM($B$4:B8) -> 30 | D8: =C8*מחשבון!$B$5 -> 5970 | E8: =מחשבון!$B$13+מחשבון!$B$9+מחשבון!$B$8+מחשבון!$B$7 -> 2423.9 | F8: =D8-E8 -> 3546.1 | G8: =SUM($F$4:F8) -> 3550.5
A9: 6 | B9: 9 | C9: =SUM($B$4:B9) -> 39 | D9: =C9*מחשבון!$B$5 -> 7761 | E9: =מחשבון!$B$13+מחשבון!$B$9+מחשבון!$B$8+מחשבון!$B$7 -> 2423.9 | F9: =D9-E9 -> 5337.1 | G9: =SUM($F$4:F9) -> 8887.6
A10: 7 | B10: 9 | C10: =SUM($B$4:B10) -> 48 | D10: =C10*מחשבון!$B$5 -> 9552 | E10: =מחשבון!$B$13+מחשבון!$B$9+מחשבון!$B$8+מחשבון!$B$7 -> 2423.9 | F10: =D10-E10 -> 7128.1 | G10: =SUM($F$4:F10) -> 16015.7
A11: 8 | B11: 10 | C11: =SUM($B$4:B11) -> 58 | D11: =C11*מחשבון!$B$5 -> 11542 | E11: =מחשבון!$B$13+מחשבון!$B$9+מחשבון!$B$8+מחשבון!$B$7 -> 2423.9 | F11: =D11-E11 -> 9118.1 | G11: =SUM($F$4:F11) -> 25133.8
A12: 9 | B12: 10 | C12: =SUM($B$4:B12) -> 68 | D12: =C12*מחשבון!$B$5 -> 13532 | E12: =מחשבון!$B$13+מחשבון!$B$9+מחשבון!$B$8+מחשבון!$B$7 -> 2423.9 | F12: =D12-E12 -> 11108.1 | G12: =SUM($F$4:F12) -> 36241.9
A13: 10 | B13: 10 | C13: =SUM($B$4:B13) -> 78 | D13: =C13*מחשבון!$B$5 -> 15522 | E13: =מחשבון!$B$13+מחשבון!$B$9+מחשבון!$B$8+מחשבון!$B$7 -> 2423.9 | F13: =D13-E13 -> 13098.1 | G13: =SUM($F$4:F13) -> 49340
A14: 11 | B14: 11 | C14: =SUM($B$4:B14) -> 89 | D14: =C14*מחשבון!$B$5 -> 17711 | E14: =מחשבון!$B$13+מחשבון!$B$9+מחשבון!$B$8+מחשבון!$B$7 -> 2423.9 | F14: =D14-E14 -> 15287.1 | G14: =SUM($F$4:F14) -> 64627.1
A15: 12 | B15: 11 | C15: =SUM($B$4:B15) -> 100 | D15: =C15*מחשבון!$B$5 -> 19900 | E15: =מחשבון!$B$13+מחשבון!$B$9+מחשבון!$B$8+מחשבון!$B$7 -> 2423.9 | F15: =D15-E15 -> 17476.1 | G15: =SUM($F$4:F15) -> 82103.2
A16: סה"כ | B16: =SUM(B4:B15) -> 100 | C16: =C15 -> 100 | D16: =SUM(D4:D15) -> 111440 | E16: =SUM(E4:E15) -> 29336.8 | F16: =SUM(F4:F15) -> 82103.2 | G16: =G15 -> 82103.2
A18: כל הסכומים נטו (ללא מע"מ). דמי הקמה (250) נכללים בעלויות חודש 1. תזרים מצטבר = רווח מצטבר מתחילת השנה.
